<?xml version="1.0"?>
<robot name="prm_robot"
  xmlns:xacro="http://ros.org/wiki/xacro">

  <!-- Definicao de Algumas Contantes -->

  <xacro:property name="base_width" value="0.35"/> <!-- Largura da base (corpo quadrado: == base_length) -->
  <xacro:property name="base_length" value="0.35"/> <!-- Comprimento da base (corpo quadrado: == base_width) -->
  <xacro:property name="base_height" value="0.18"/> <!-- Altura da base -->

  <xacro:property name="wheel_radius" value="0.10"/> <!-- Raio da roda -->
  <xacro:property name="wheel_width" value="0.04"/> <!-- Largura da roda -->
  <xacro:property name="wheel_ygap" value="0.025"/> <!-- Distancia entre as rodas -->
  <xacro:property name="wheel_zoff" value="0.05"/> <!-- Deslocamento da roda em Z -->
  <xacro:property name="wheel_xoff" value="0.0"/> <!-- Rodas no eixo do centro: gira no lugar sem varrer o corpo -->

  <xacro:property name="caster_xoff" value="0.14"/> <!-- Deslocamento do caster em X -->

  <!-- Definição de algumas propriedades inerciais -->
  <xacro:macro name="box_inertia" params="m w h d">
    <inertial>
      <origin xyz="0 0 0" rpy="${pi/2} 0 ${pi/2}"/>
      <mass value="${m}"/>
      <inertia ixx="${(m/12) * (h*h + d*d)}" ixy="0.0" ixz="0.0" iyy="${(m/12) * (w*w + d*d)}" iyz="0.0" izz="${(m/12) * (w*w + h*h)}"/>
    </inertial>
  </xacro:macro>

  <xacro:macro name="cylinder_inertia" params="m r h">
    <inertial>
      <origin xyz="0 0 0" rpy="${pi/2} 0 0" />
      <mass value="${m}"/>
      <inertia ixx="${(m/12) * (3*r*r + h*h)}" ixy = "0" ixz = "0" iyy="${(m/12) * (3*r*r + h*h)}" iyz = "0" izz="${(m/2) * (r*r)}"/>
    </inertial>
  </xacro:macro>

  <xacro:macro name="sphere_inertia" params="m r">
    <inertial>
      <mass value="${m}"/>
      <inertia ixx="${(2/5) * m * (r*r)}" ixy="0.0" ixz="0.0" iyy="${(2/5) * m * (r*r)}" iyz="0.0" izz="${(2/5) * m * (r*r)}"/>
    </inertial>
  </xacro:macro>

  <!-- Definindo plugin para publiar a pose do robo -->
  <gazebo>
    <plugin filename="libignition-gazebo-pose-publisher-system" name="ignition::gazebo::systems::PosePublisher">
      <publish_link_pose>false</publish_link_pose>
      <publish_model_pose>true</publish_model_pose>
      <publish_nested_model_pose>true</publish_nested_model_pose>
      <use_pose_vector_msg>false</use_pose_vector_msg>
      <publish_visual_pose>false</publish_visual_pose>
      <update_frequency>10</update_frequency>
    </plugin>
  </gazebo>

  <!-- Definindo a Base do Robô -->
  <link name="base_link">
    <visual>
      <geometry>
        <box size="${base_length} ${base_width} ${base_height}"/>
      </geometry>
      <material name="DarkBlue">
        <color rgba="0.09 0.30 0.46 1.0"/>
      </material>
    </visual>

    <collision>
      <geometry>
        <box size="${base_length} ${base_width} ${base_height}"/>
      </geometry>
    </collision>

    <xacro:box_inertia m="2.5" w="${base_width}" d="${base_length}" h="${base_height}"/>
  </link>

  <!-- Definindo a Base do Robô (base footprint) -->
  <link name="base_footprint">
    <xacro:box_inertia m="0" w="0" d="0" h="0"/>
  </link>

  <joint name="base_joint" type="fixed">
    <parent link="base_link"/>
    <child link="base_footprint"/>
    <origin xyz="0.0 0.0 ${-(wheel_radius+wheel_zoff)}" rpy="0 0 0"/>
  </joint>

  <!-- Definindo as Rodas do Robô -->
  <!-- Parâmetros: prefix: drivewhl_l, drivewhl_r -->
  <xacro:macro name="wheel" params="prefix x_reflect y_reflect">
    <link name="${prefix}_link">
      <visual>
        <origin xyz="0 0 0" rpy="${pi/2} 0 0"/>
        <geometry>
          <cylinder radius="${wheel_radius}" length="${wheel_width}"/>
        </geometry>
        <material name="LightBlue">
          <color rgba="0.11 0.37 0.56 1.0"/>
        </material>
      </visual>

      <collision>
        <origin xyz="0 0 0" rpy="${pi/2} 0 0"/>
        <geometry>
          <cylinder radius="${wheel_radius}" length="${wheel_width}"/>
        </geometry>
      </collision>

      <xacro:cylinder_inertia m="0.05" r="${wheel_radius}" h="${wheel_width}"/>
    </link>

    <joint name="${prefix}_joint" type="continuous">
      <parent link="base_link"/>
      <child link="${prefix}_link"/>
      <origin xyz="${x_reflect*wheel_xoff} ${y_reflect*(base_width/2+wheel_ygap)} ${-wheel_zoff}" rpy="0 0 0"/>
      <axis xyz="0 1 0"/>
      <dynamics damping="0.2"/>
    </joint>
  </xacro:macro>

  <xacro:wheel prefix="drivewhl_l" x_reflect="-1" y_reflect="1" />
  <xacro:wheel prefix="drivewhl_r" x_reflect="-1" y_reflect="-1" />

  <!-- High friction on drive wheels (prevents slip) -->
  <gazebo reference="drivewhl_l_link">
    <mu1>100.0</mu1>
    <mu2>50.0</mu2>
    <kp>1e6</kp>
    <kd>1.0</kd>
  </gazebo>
  <gazebo reference="drivewhl_r_link">
    <mu1>100.0</mu1>
    <mu2>50.0</mu2>
    <kp>1e6</kp>
    <kd>1.0</kd>
  </gazebo>

  <link name="front_caster">
    <visual>
      <geometry>
        <sphere radius="${(wheel_radius+wheel_zoff-(base_height/2))}"/>
      </geometry>
      <material name="DarkBlue">
        <color rgba="0.09 0.30 0.46 1.0"/>
      </material>
    </visual>

    <collision>
      <origin xyz="0 0 0" rpy="0 0 0"/>
      <geometry>
        <sphere radius="${(wheel_radius+wheel_zoff-(base_height/2))}"/>
      </geometry>
    </collision>

    <xacro:sphere_inertia m="0.005" r="${(wheel_radius+wheel_zoff-(base_height/2))}"/>
  </link>

  <joint name="caster_joint" type="fixed">
    <parent link="base_link"/>
    <child link="front_caster"/>
    <origin xyz="${caster_xoff} 0.0 ${-(base_height/2)}" rpy="0 0 0"/>
  </joint>

  <!-- Very low friction on caster so it rotates freely -->
  <gazebo reference="front_caster">
    <mu1>0.01</mu1>
    <mu2>0.01</mu2>
    <kp>100000.0</kp>
    <kd>1.0</kd>
  </gazebo>

  <!-- Caster traseiro: com as rodas no centro, dá apoio fore/aft (não tomba). -->
  <link name="rear_caster">
    <visual>
      <geometry>
        <sphere radius="${(wheel_radius+wheel_zoff-(base_height/2))}"/>
      </geometry>
      <material name="DarkBlue">
        <color rgba="0.09 0.30 0.46 1.0"/>
      </material>
    </visual>

    <collision>
      <origin xyz="0 0 0" rpy="0 0 0"/>
      <geometry>
        <sphere radius="${(wheel_radius+wheel_zoff-(base_height/2))}"/>
      </geometry>
    </collision>

    <xacro:sphere_inertia m="0.005" r="${(wheel_radius+wheel_zoff-(base_height/2))}"/>
  </link>

  <joint name="rear_caster_joint" type="fixed">
    <parent link="base_link"/>
    <child link="rear_caster"/>
    <origin xyz="${-caster_xoff} 0.0 ${-(base_height/2)}" rpy="0 0 0"/>
  </joint>

  <gazebo reference="rear_caster">
    <mu1>0.01</mu1>
    <mu2>0.01</mu2>
    <kp>100000.0</kp>
    <kd>1.0</kd>
  </gazebo>

  <!-- Definindo a IMU do Robô (física) -->
  <link name="imu_link">
    <visual>
      <geometry>
        <box size="0.1 0.1 0.1"/>
      </geometry>
    </visual>

    <collision>
      <geometry>
        <box size="0.1 0.1 0.1"/>
      </geometry>
    </collision>

    <xacro:box_inertia m="0.001" w="0.1" d="0.1" h="0.1"/>        
  </link>

  <!-- Definindo o sensor IMU no Gazebo -->
  <gazebo reference="imu_link">
    <sensor name="imu_sensor" type="imu">
      <ignition_frame_id>imu_link</ignition_frame_id>
      <plugin filename="ignition-gazebo-imu-system" name="ignition::gazebo::systems::Imu">
      </plugin>

      <topic>imu</topic>
      <always_on>true</always_on>
      <update_rate>50</update_rate>
      <visualize>true</visualize>
      <imu>
        <angular_velocity>
          <x>
            <noise type="gaussian">
              <mean>0.0</mean>
              <stddev>2e-4</stddev>
              <bias_mean>0.0000075</bias_mean>
              <bias_stddev>0.0000008</bias_stddev>
            </noise>
          </x>
          <y>
            <noise type="gaussian">
              <mean>0.0</mean>
              <stddev>2e-4</stddev>
              <bias_mean>0.0000075</bias_mean>
              <bias_stddev>0.0000008</bias_stddev>
            </noise>
          </y>
          <z>
            <noise type="gaussian">
              <mean>0.0</mean>
              <stddev>2e-4</stddev>
              <bias_mean>0.0000075</bias_mean>
              <bias_stddev>0.0000008</bias_stddev>
            </noise>
          </z>
        </angular_velocity>
        <linear_acceleration>
          <x>
            <noise type="gaussian">
              <mean>0.0</mean>
              <stddev>1.7e-2</stddev>
              <bias_mean>0.1</bias_mean>
              <bias_stddev>0.001</bias_stddev>
            </noise>
          </x>
          <y>
            <noise type="gaussian">
              <mean>0.0</mean>
              <stddev>1.7e-2</stddev>
              <bias_mean>0.1</bias_mean>
              <bias_stddev>0.001</bias_stddev>
            </noise>
          </y>
          <z>
            <noise type="gaussian">
              <mean>0.0</mean>
              <stddev>1.7e-2</stddev>
              <bias_mean>0.1</bias_mean>
              <bias_stddev>0.001</bias_stddev>
            </noise>
          </z>
        </linear_acceleration>
      </imu>
    </sensor>
  </gazebo>

  <!-- Ligando a IMU a base do robô -->
  <joint name="imu_joint" type="fixed">
    <parent link="base_link"/>
    <child link="imu_link"/>
    <origin xyz="0 0 0.01"/>
  </joint>

  <!-- Define um sistema de controle ROS 2 utilizando a infraestrutura ros2_control -->
  <ros2_control name="IgnitionSystem" type="system">
    
    <!-- Seção de hardware do sistema, onde é especificado o plugin que fará a ponte entre o Gazebo (Ignition) e o ros2_control -->
    <hardware>
      <!-- Plugin que permite a integração entre o Ignition Gazebo e o framework ros2_control -->
      <plugin>ign_ros2_control/IgnitionSystem</plugin>
    </hardware>

    <!-- Definição do primeiro atuador, correspondente à roda esquerda ("drive wheel left") -->
    <joint name="drivewhl_l_joint">

      <!-- Interface de comando de velocidade angular (por exemplo, rad/s) para essa junta -->
      <command_interface name="velocity">
        <!-- Valor mínimo permitido para o comando de velocidade (limite inferior) -->
        <param name="min">-15</param>
        <!-- Valor máximo permitido para o comando de velocidade (limite superior) -->
        <param name="max">15</param>
      </command_interface>

      <!-- Interface de estado que fornece a posição atual da junta (por exemplo, em radianos) -->
      <state_interface name="position"/>
      <!-- Interface de estado que fornece a velocidade atual da junta (por exemplo, em rad/s) -->
      <state_interface name="velocity"/>
    </joint>

    <!-- Definição do segundo atuador, correspondente à roda direita ("drive wheel right") -->
    <joint name="drivewhl_r_joint">

      <!-- Interface de comando de velocidade angular para essa junta -->
      <command_interface name="velocity">
        <!-- Limite inferior da velocidade que pode ser comandada -->
        <param name="min">-15</param>
        <!-- Limite superior da velocidade que pode ser comandada -->
        <param name="max">15</param>
      </command_interface>

      <!-- Interface de estado para leitura da posição da junta -->
      <state_interface name="position"/>

      <!-- Interface de estado para leitura da velocidade da junta -->
      <state_interface name="velocity"/>
    </joint>

    <!-- Junta 1 (ombro/base do braço): PITCH vertical, levanta o braço 0 -> 45 graus -->
    <joint name="shoulder_pitch">
      <command_interface name="position">
        <param name="min">0.0</param>
        <param name="max">0.785398</param>
      </command_interface>
      <!-- Início em 0 graus: braço apontando reto para a frente -->
      <state_interface name="position">
        <param name="initial_value">0.0</param>
      </state_interface>
      <state_interface name="velocity"/>
    </joint>

    <joint name="gripper_extension">
      <command_interface name="position">
        <param name="min">-1.5708</param>
        <param name="max">0.0</param>
      </command_interface>
      <!-- Início RETRAÍDO em -90°: braço recolhido ao lado já no spawn. Estender
           leva a 0 (90° de varredura) = diretamente à frente do robô. -->
      <state_interface name="position">
        <param name="initial_value">-1.5708</param>
      </state_interface>
      <state_interface name="velocity"/>
    </joint>

    <joint name="arm_elbow">
      <command_interface name="position">
        <param name="min">-1.5708</param>
        <param name="max">0.0</param>
      </command_interface>
      <state_interface name="position">
        <param name="initial_value">-1.5708</param>
      </state_interface>
      <state_interface name="velocity"/>
    </joint>

    <joint name="left_gripper_joint">
      <command_interface name="position">
        <param name="min">0.0</param>
        <param name="max">0.06</param>
      </command_interface>

      <state_interface name="position">
        <param name="initial_value">0.0</param>
      </state_interface>
      <state_interface name="velocity"/>
    </joint>

    <joint name="right_gripper_joint">
      <command_interface name="position">
        <param name="min">-0.06</param>
        <param name="max">0.0</param>
      </command_interface>

      <state_interface name="position">
        <param name="initial_value">0.0</param>
      </state_interface>
      <state_interface name="velocity"/>
    </joint>

  </ros2_control>

  <gazebo>
    <plugin filename="ign_ros2_control-system" name="ign_ros2_control::IgnitionROS2ControlPlugin">
      <!-- Config DENTRO do bb8_control (repo alvo): gripper_controller com os 5
           joints que o gripper_server publica (shoulder_pitch, gripper_extension,
           arm_elbow, right/left_gripper_joint). O config do prm_2026 só tinha 3
           joints -> update() do JointGroupPositionController dava ERROR (5 != 3). -->
      <parameters>$(find bb8_control)/config/controller_config.yaml</parameters>
    </plugin>
  </gazebo>

  <link name="lidar_link">
    <inertial>
      <origin xyz="0 0 0" rpy="0 0 0"/>
      <mass value="0.125"/>
      <inertia ixx="0.001" ixy="0" ixz="0" iyy="0.001" iyz="0" izz="0.001" />
    </inertial>

    <collision>
      <origin xyz="0 0 0" rpy="0 0 0"/>
      <geometry>
        <cylinder radius="0.0508" length="0.055"/>
      </geometry>
    </collision>

    <visual>
      <origin xyz="0 0 0" rpy="0 0 0"/>
      <geometry>
        <cylinder radius="0.0508" length="0.055"/>
      </geometry>
      <material name="LightBlue">
        <color rgba="0.11 0.37 0.56 1.0"/>
      </material>
    </visual>
  </link>

  <joint name="lidar_joint" type="fixed">
    <parent link="base_link"/>
    <child link="lidar_link"/>
    <origin xyz="0 0 0.12" rpy="0 0 0"/>
  </joint>

  <gazebo reference="lidar_link">
    <sensor name="lidar" type="gpu_lidar">
      <ignition_frame_id>lidar_link</ignition_frame_id>
      <topic>scan</topic>
      <always_on>true</always_on>
      <visualize>true</visualize>
      <update_rate>20</update_rate>
      <ray>
        <scan>
          <horizontal>
            <samples>360</samples>
            <resolution>1.000000</resolution>
            <min_angle>0.000000</min_angle>
            <max_angle>6.280000</max_angle>
          </horizontal>
        </scan>
        <range>
          <min>0.120000</min>
          <max>5.0</max>
          <resolution>0.05000</resolution>
        </range>
        <noise>
          <type>gaussian</type>
          <mean>0.0</mean>
          <stddev>0.01</stddev>
        </noise>
      </ray>
    </sensor>
  </gazebo>

  <link name="camera_link">
    <visual>
      <origin xyz="0 0 0" rpy="0 0 0"/>
      <geometry>
        <box size="0.015 0.130 0.022"/>
      </geometry>
      <material name="LightBlue">
        <color rgba="0.11 0.37 0.56 1.0"/>
      </material>
    </visual>

    <collision>
      <origin xyz="0 0 0" rpy="0 0 0"/>
      <geometry>
        <box size="0.015 0.130 0.022"/>
      </geometry>
    </collision>

    <inertial>
      <origin xyz="0 0 0" rpy="0 0 0"/>
      <mass value="0.035"/>
      <inertia ixx="0.001" ixy="0" ixz="0" iyy="0.001" iyz="0" izz="0.001" />
    </inertial>
  </link>

  <joint name="camera_joint" type="fixed">
    <parent link="base_link"/>
    <child link="camera_link"/>
    <!-- Câmera levemente acima do plano do braço retraído (arm_base z=0.05),
         senão o braço recolhido fica na frente da lente. -->
    <origin xyz="0.18 0 0.085" rpy="0 0 0"/>
  </joint>

  <link name="camera_frame"/>

  <joint name="camera_frame_joint" type="fixed">
    <origin xyz="0 0 0" rpy="${-pi/2} 0 ${-pi/2}"/>
    <parent link="camera_link"/>
    <child link="camera_frame"/>
  </joint>

  <gazebo reference="camera_link">

    <!-- Insere uma camera comum RGB -->
    <!-- <sensor name="robot_cam" type="camera">
      <camera>
        <horizontal_fov>1.57</horizontal_fov>
        <image>
          <width>320</width>
          <height>240</height>
        </image>
        <clip>
          <near>0.1</near>
          <far>100</far>
        </clip>
      </camera>
      <always_on>1</always_on>
      <update_rate>15</update_rate>
      <visualize>true</visualize>
      <topic>robot_cam</topic>
      <enable_metrics>true</enable_metrics>
    </sensor> -->

    <!-- RGB camera REMOVIDA: mantida apenas a câmera semântica (corta 1 render
         pass por frame). bb8_visual_slam (rtabmap) fica sem fonte RGB. -->

    <!-- Insere uma camera com segmentacao semantica -->
    <sensor name="robot_cam" type="segmentation">
      <topic>robot_cam</topic>
      <camera>
        <segmentation_type>semantic</segmentation_type>
        <horizontal_fov>1.9</horizontal_fov> <!-- FOV largo: pega a flag mais de lado durante a exploração (vision_processor.camera_hfov_deg deve casar) -->
        <image>
          <width>320</width>
          <height>240</height>
        </image>
        <clip>
          <near>0.1</near>
          <far>100</far>
        </clip>
      </camera>
      <always_on>1</always_on>
      <update_rate>15</update_rate>
      <visualize>true</visualize>
    </sensor>

    <!-- Insere uma camera bounding box 2D completo -->
    <!-- <sensor name="full_2d" type="boundingbox_camera">
      <topic>boxes_full_2d</topic>
      <camera>
        <box_type>full_2d</box_type>
        <horizontal_fov>1.57</horizontal_fov>
        <image>
          <width>320</width>
          <height>240</height>
        </image>
        <clip>
          <near>0.1</near>
          <far>10</far>
        </clip>
        <save enabled="false">
          <path>bounding_box_full_2d_data</path>
        </save>
      </camera>
      <always_on>1</always_on>
      <update_rate>15</update_rate>
      <visualize>true</visualize>
    </sensor> -->

    <!-- Insere uma camera bounding box 2D -->
    <!-- <sensor name="visible_2d" type="boundingbox_camera">
      <topic>boxes_visible_2d</topic>
      <camera>
        <box_type>visible_2d</box_type>
        <horizontal_fov>1.57</horizontal_fov>
        <image>
          <width>320</width>
          <height>240</height>
        </image>
        <clip>
          <near>0.1</near>
          <far>10</far>
        </clip>
        <save enabled="false">
          <path>bounding_box_visible_2d_data</path>
        </save>
      </camera>
      <always_on>1</always_on>
      <update_rate>15</update_rate>
      <visualize>true</visualize>
    </sensor> -->

    <!-- Insere uma camera bounding box 3D -->
    <!-- <sensor name="3d" type="boundingbox_camera">
      <topic>boxes_3d</topic>
      <camera>
        <box_type>3d</box_type>
        <horizontal_fov>1.57</horizontal_fov>
        <image>
          <width>320</width>
          <height>240</height>
        </image>
        <clip>
          <near>0.1</near>
          <far>10</far>
        </clip>
        <save enabled="false">
          <path>bounding_box_3d_data</path>
        </save>
      </camera>
      <always_on>1</always_on>
      <update_rate>15</update_rate>
      <visualize>true</visualize>
    </sensor> -->

  </gazebo>

  <!-- Junta 1 - Ombro/base do braço: PITCH no plano vertical.
       axis (0 -1 0): rotação positiva LEVANTA a ponta do braço.
       lower=0 (reto para a frente), upper=0.785398 rad (45 graus). -->
  <joint name="shoulder_pitch" type="revolute">
    <axis xyz="0 -1 0"/>
    <limit effort="50.0" lower="0.0" upper="0.785398" velocity="3.0"/>
    <!-- Realocado para o TOPO do corpo quadrado (z=base_height/2=0.09), recuado
         do lidar central (x=0.13 > raio lidar 0.05) e à frente p/ alcançar flags. -->
    <origin rpy="0 0 0" xyz="0.13 0 0.09"/>
    <parent link="base_link"/>
    <child link="arm_base"/>
  </joint>

  <!-- Link curto do ombro: tudo abaixo herda o pitch desta junta -->
  <link name="arm_base">
    <visual>
      <geometry>
        <cylinder length="0.04" radius="0.012"/>
      </geometry>
      <origin rpy="0 1.57075 0" xyz="0.02 0 0"/>
      <material name="LightBlue">
        <color rgba="0.11 0.37 0.56 1.0"/>
      </material>
    </visual>
    <!-- Colisão removida: elo estrutural interno, nunca toca nada. Simplifica física. -->
    <xacro:cylinder_inertia m="0.01" r="0.012" h="0.04"/>
  </link>

  <!-- Junta 2: horizontal (yaw, Z-axis), varre o braço lateralmente.
       Re-parented para arm_base para herdar o pitch da Junta 1. -->
  <joint name="gripper_extension" type="revolute">
    <axis xyz="0 0 1"/>
    <!-- Junta horizontal: amplitude limitada a 90° (-1.5708 a 0). Velocidade 2.0 (desdobra rápido). -->
    <limit effort="50.0" lower="-1.5708" upper="0.0" velocity="3.0"/>
    <origin rpy="0 0 0" xyz="0.04 0 0"/>
    <parent link="arm_base"/>
    <child link="upper_arm"/>
  </joint>

  <!-- Upper arm segment (shoulder → elbow) -->
  <link name="upper_arm">
    <visual>
      <geometry>
        <cylinder length="0.10" radius="0.01"/>
      </geometry>
      <origin rpy="0 1.57075 0" xyz="0.05 0 0"/>
    </visual>
    <!-- Colisão removida: elo estrutural interno. Simplifica física. -->
    <xacro:cylinder_inertia m="0.005" r="0.01" h="0.10"/>
  </link>

  <!-- Elbow: folds lower arm back toward body (same Z-axis rotation) -->
  <joint name="arm_elbow" type="revolute">
    <axis xyz="0 0 1"/>
    <!-- Junta horizontal: amplitude limitada a 90° (-1.5708 a 0). Velocidade 2.0 (desdobra rápido). -->
    <limit effort="50.0" lower="-1.5708" upper="0.0" velocity="3.0"/>
    <origin xyz="0.10 0 0" rpy="0 0 0"/>
    <parent link="upper_arm"/>
    <child link="gripper_pole"/>
  </joint>

  <link name="gripper_pole">
    <visual>
      <geometry>
        <cylinder length="0.12" radius="0.01"/>
      </geometry>
      <origin rpy="0 1.57075 0" xyz="0.06 0 0"/>
    </visual>

    <!-- Colisão removida: elo estrutural interno. Simplifica física. -->

    <xacro:cylinder_inertia m="0.01" r="0.01" h="0.12"/>

  </link>

  <joint name="left_gripper_joint" type="prismatic">
    <axis xyz="0 1 0"/>
    <limit effort="100.0" lower="0.0" upper="0.06" velocity="0.25"/>

    <origin rpy="0 0 0" xyz="0.12 0.01 0"/>
    <parent link="gripper_pole"/>
    <child link="left_gripper"/>
  </joint>

  <link name="left_gripper">
    <visual>
      <geometry>
        <box size="0.1 0.02 0.02"/> <!-- Comprimento, largura, altura -->
      </geometry>
    </visual>

    <collision>
      <geometry>
        <box size="0.1 0.02 0.02"/>
      </geometry>
    </collision>

    <xacro:box_inertia m="0.015" w="0.02" h="0.02" d="0.1"/>

  </link>

  <joint name="left_tip_joint" type="fixed">
    <origin rpy="0.0 0 0" xyz="0.06 0.001 0"/>
    <parent link="left_gripper"/>
    <child link="left_tip"/>
  </joint>

  <link name="left_tip">
   
    <visual>
      <origin rpy="0 0 -0.1" xyz="0.03 0 0"/>
      <geometry>
        <box size="0.06 0.01 0.01"/>
      </geometry>
    </visual>

    <collision>
      <origin rpy="0 0 -0.1" xyz="0.03 0 0"/>
      <geometry>
        <box size="0.06 0.01 0.01"/>
      </geometry>
    </collision>


    <xacro:box_inertia m="0.005" w="0.01" h="0.01" d="0.06"/>

  </link>

  <joint name="right_gripper_joint" type="prismatic">
    <axis xyz="0 1 0"/>
    <limit effort="100.0" lower="-0.06" upper="0" velocity="0.25"/>
    <origin rpy="0 0 0" xyz="0.12 -0.01 0"/>

    <parent link="gripper_pole"/>
    <child link="right_gripper"/>
  </joint>

  <link name="right_gripper">
    <visual>
      <origin rpy="-3.1415 0 0" xyz="0 0 0"/>
      <geometry>
        <box size="0.1 0.02 0.02"/>
      </geometry>
    </visual>

    <collision>
      <origin rpy="-3.1415 0 0" xyz="0 0 0"/>
      <geometry>
        <box size="0.1 0.02 0.02"/>
      </geometry>
    </collision>

    <xacro:box_inertia m="0.015" w="0.02" h="0.02" d="0.1"/>

  </link>

  <joint name="right_tip_joint" type="fixed">
    <origin rpy="-3.1415 0 0" xyz="0.06 -0.001 0"/>
    <parent link="right_gripper"/>
    <child link="right_tip"/>
  </joint>

  <link name="right_tip">
    <visual>
      <origin rpy="0 0 -0.1" xyz="0.03 0 0"/>
      <geometry>
        <box size="0.06 0.01 0.01"/>
      </geometry>
    </visual>

    <collision>
      <origin rpy="0 0 -0.1" xyz="0.03 0 0"/>
      <geometry>
        <box size="0.06 0.01 0.01"/>
      </geometry>
    </collision>

    <xacro:box_inertia m="0.005" w="0.01" h="0.01" d="0.06"/>


  </link>

  <!-- Alto atrito + contato rígido nos dedos/pontas da garra: segura a haste da
       flag firme, sem escorregar (a flag é leve, então atrito alto resolve). -->
  <xacro:macro name="grip_friction" params="ref">
    <gazebo reference="${ref}">
      <mu1>200.0</mu1>
      <mu2>200.0</mu2>
      <kp>1e6</kp>
      <kd>1.0</kd>
      <minDepth>0.001</minDepth>
      <maxVel>0.0</maxVel>
    </gazebo>
  </xacro:macro>
  <xacro:grip_friction ref="left_gripper"/>
  <xacro:grip_friction ref="right_gripper"/>
  <xacro:grip_friction ref="left_tip"/>
  <xacro:grip_friction ref="right_tip"/>

</robot>
